2021-07-25 21:41:27,814 - instabot version: 0.117.0 (bot) - INFO - Instabot version: 0.117.0 Started
2021-07-25 21:41:27,814 - instabot version: 0.117.0 (bot) - DEBUG - Bot imported from /Users/braninpodolski/Library/Python/3.9/lib/python/site-packages/instabot/bot/bot.py
2021-07-25 21:41:27,815 - instabot version: 0.117.0 (api_login) - INFO - Not yet logged in starting: PRE-LOGIN FLOW!
2021-07-25 21:41:27,832 - instabot version: 0.117.0 (api) - WARNING - HTTPSConnectionPool(host='i.instagram.com', port=443): Max retries exceeded with url: /api/v1/accounts/get_prefill_candidates/ (Caused by NewConnectionError('<urllib3.connection.HTTPSConnection object at 0x1076c9ee0>: Failed to establish a new connection: [Errno 8] nodename nor servname provided, or not known'))
2021-07-25 21:41:27,835 - instabot version: 0.117.0 (api) - WARNING - HTTPSConnectionPool(host='i.instagram.com', port=443): Max retries exceeded with url: /api/v1/qe/sync/ (Caused by NewConnectionError('<urllib3.connection.HTTPSConnection object at 0x1076c9f10>: Failed to establish a new connection: [Errno 8] nodename nor servname provided, or not known'))
2021-07-25 21:41:27,839 - instabot version: 0.117.0 (api) - WARNING - HTTPSConnectionPool(host='i.instagram.com', port=443): Max retries exceeded with url: /api/v1/launcher/sync/ (Caused by NewConnectionError('<urllib3.connection.HTTPSConnection object at 0x1076c9eb0>: Failed to establish a new connection: [Errno 8] nodename nor servname provided, or not known'))
2021-07-25 21:41:27,843 - instabot version: 0.117.0 (api) - WARNING - HTTPSConnectionPool(host='i.instagram.com', port=443): Max retries exceeded with url: /api/v1/accounts/contact_point_prefill/ (Caused by NewConnectionError('<urllib3.connection.HTTPSConnection object at 0x1076c9250>: Failed to establish a new connection: [Errno 8] nodename nor servname provided, or not known'))
